Workbook

Sheet Leads
A1: ID | B1: Prioridade | C1: Pontuação | D1: Estado | E1: Responsável | F1: Ângulo | G1: Distrito | H1: Concelho | I1: Localidade | J1: Escola | K1: Grupo | L1: Contacto | M1: Cargo | N1: Telefone | O1: Telemóvel | P1: WhatsApp | Q1: Email | R1: Website | S1: Facebook | T1: Instagram | U1: Google ★ | V1: Google n.º | W1: Software atual | X1: Marcação de aulas | Y1: Sábado | Z1: Horário | AA1: Exames 2021 | AB1: Categorias | AC1: Sinais de dor | AD1: Motivo prioridade | AE1: Próxima ação | AF1: Data próxima ação | AG1: Último contacto | AH1: Passo seq | AI1: Próximo envio | AJ1: Motivo perda | AK1: Notas | AL1: Link WhatsApp | AM1: Software evidência | AN1: Morada | AO1: Fontes | AP1: Thread ID
A2: 1 | B2: A | C2: 10.5 | D2: Novo | E2: Pedro | F2: grupo | G2: Leiria | H2: Caldas da Rainha | I2: Caldas da Rainha | J2: Escola de Condução Bordalo Pinheiro | K2: Bordalo (grupo, segundo bomcondutor) | N2: 262 880 399 | O2: 916 267 390 | S2: https://www.facebook.com/pages/Escola-de-condução-Bordalo-Pinheiro/127727473957013 | U2: 2.4 | V2: 18 | X2: Telefone/presencial; reviews indicam falta de aviso de cancelamentos | AA2: 1132 | AC2: "Falta de organização, desmarcam aulas sem telefonar... já é a quinta aula que não ligam a avisar de cancelamento" (Google 1★, 03/2023) https://escola-de-conducao.pt/escola-de-conducao-bordalo-pinheiro-306171.html; "Não me mandavam mensagem para cancelamento de aulas" (Google 2★, 07/2023) https://escola-de-conducao.pt/escola-de-conducao-bordalo-pinheiro-306171.html; "falta de organização enorme" (Google 1★, 12/2022) https://escola-de-conducao.pt/escola-de-conducao-bordalo-pinheiro-306171.html | AD2: MELHOR LEAD: maior volume do distrito (1132 exames 2021) + dor exatamente no problema da Convlyx (cancelamentos sem aviso, desorganização) | AH2: 0 | AL2: =IF(IF(O2<>"",O2,IF(LEFT(TRIM(N2),1)="9",N2,""))="","",HYPERLINK("https://wa.me/351"&LEFT(SUBSTITUTE(SUBSTITUTE(SUBSTITUTE(IF(O2<>"",O2,IF(LEFT(TRIM(N2),1)="9",N2,""))," ",""),"+351",""),"-",""),9),"Abrir WhatsApp")) -> Abrir WhatsApp | AN2: Rua Dr. Ângelo Ferrari, 5 R/c Dto - 2500-113 Caldas da Rainha | AO2: https://passaprimeira.xyz/distritos-regioes/leiria/concelhos/caldas-da-rainha/escolas/bordalo-pinheiro-00913/; https://escola-de-conducao.pt/escola-de-conducao-bordalo-pinheiro-306171.html; https://www.bomcondutor.pt/escolas/escola/bordalo-pinheiro; https://www.andardemoto.pt/escolas-de-conducao/dir/d/leiria/c/caldas-da-rainha/p-2199/bordalo-pinheiro/
A3: 2 | B3: A | C3: 10.4 | D3: Novo | E3: Pedro | F3: grupo | G3: Leiria | H3: Caldas da Rainha | I3: Caldas da Rainha | J3: Escola de Condução Caldas (EC Caldas) | K3: Provável grupo EC Caldas (Nova Rainha, Cardal-Pombal; review refere escola em Quinta do Conde) - bomcondutor: "Segurança Activa" | N3: 262 877 371 | O3: 919 796 968 | R3: http://www.eccaldas.pt/ | S3: https://www.facebook.com/ECCALDAS | U3: 3 | V3: 83 | W3: Área do Aluno própria (login Joomla no site) | X3: Telefone/presencial; área do aluno web legada | Y3: Sim | Z3: Secretaria 2ª-6ª 10h-12h30 / 14h-20h; Sábado 9h-13h (ABERTO sábado); aulas teóricas sáb 10h, 11h, 12h | AA3: 729 | AB3: A, B (motociclos e ligeiros) | AC3: "Falta de organização, falta de informação, prazos longos" (Google 1★, 03/2024) https://escola-de-conducao.pt/escola-de-conducao-caldas-306021.html; "escola da Quinta do conde muito má super falta de organização alunos com muito tempo de espera fazer aulas" (Google 1★, 04/2022) https://escola-de-conducao.pt/escola-de-conducao-caldas-306021.html; muitas queixas sobre trato dos instrutores | AD3: Volume alto (729 exames 2021), provável grupo multi-escola, dor em organização/esperas; área do aluno muito antiga | AH3: 0 | AL3: =IF(IF(O3<>"",O3,IF(LEFT(TRIM(N3),1)="9",N3,""))="","",HYPERLINK("https://wa.me/351"&LEFT(SUBSTITUTE(SUBSTITUTE(SUBSTITUTE(IF(O3<>"",O3,IF(LEFT(TRIM(N3),1)="9",N3,""))," ",""),"+351",""),"-",""),9),"Abrir WhatsApp")) -> Abrir WhatsApp | AM3: http://www.eccaldas.pt/index.php/alunos - "Entrar na Área do Aluno" (Utilizador/Senha), site Joomla de 2012 | AN3: Av. Eng. Luís Paiva e Sousa, 22-B - 2500-329 Caldas da Rainha | AO3: https://passaprimeira.xyz/distritos-regioes/leiria/concelhos/caldas-da-rainha/escolas/caldas-01297/; http://www.eccaldas.pt/index.php/contactos; http://www.eccaldas.pt/index.php/horarios; https://escola-de-conducao.pt/escola-de-conducao-caldas-306021.html; https://www.bomcondutor.pt/escolas/escola/caldas
A4: 3 | B4: A | C4: 10.3 | D4: Novo | E4: Pedro | F4: grupo | G4: Lisboa | H4: Alenquer | I4: Alenquer | J4: Escola de Condução de Alenquer (Segurança Máxima; ex-Ideal de Alenquer) | K4: Segurança Máxima (~70 escolas: Grande Lisboa, Setúbal, Madeira) | N4: 263 711 912 | O4: 963 904 022 | Q4: alenquer@segurancamaxima.pt | R4: https://www.segurancamaxima.pt/escolas-de-conducao/escola-de-conducao-de-alenquer/ | S4: https://www.facebook.com/grupo.seguranca.maxima | T4: https://www.instagram.com/seguranca.maxima/ | U4: 3.7 | V4: 53 | W4: Softdrive (gestão/horários) + e-learning do grupo | X4: Secretaria/telefone; reviews dizem que se marca 'quando tem disponibilidade e não o aluno' | Y4: Sim | Z4: Secretaria dias úteis 09h-20h, Sábado 09h-13h; aulas de condução dias úteis 07h-20h50, Sábado 09h-13h (ABERTO sábado de manhã) | AA4: 691 | AB4: AM, A1, A2, A, B, B1, B+E, C, C1, C+E, D, D1, D+E | AC4: 'para marcar aulas é quando tem disponibilidade e não o aluno' (Google, 2022); 'a quase 90 dias a espera de vaga para fazer minha primeira aula prática e ainda a secretária disse que aulas podem ser cancelada' (Google, 2021); 'Atendimento demorado e ineficaz pelo telemóvel' (Google, 2023) - https://escola-de-conducao.pt/escola-de-conducao-seguranca-maxima-de-alenquer-lda-306155.html; Queixa 2019: aluno do Carregado com aulas em Alenquer e informação errada sobre a hora do exame - https://portaldaqueixa.com/brands/seguranca-maxima-escolas-de-conducao/complaints/seguranca-maxima-escolas-de-conducao-marcacao-de-exame-de-mecanica-para-categoria-c-27254919 | AD4: Muita evidência de dor (marcação, esperas, cancelamentos) e maior volume da zona (691). Atenção: grande grupo com decisão centralizada em Lisboa e já usa Softdrive | AH4: 0 | AL4: =IF(IF(O4<>"",O4,IF(LEFT(TRIM(N4),1)="9",N4,""))="","",HYPERLINK("https://wa.me/351"&LEFT(SUBSTITUTE(SUBSTITUTE(SUBSTITUTE(IF(O4<>"",O4,IF(LEFT(TRIM(N4),1)="9",N4,""))," ",""),"+351",""),"-",""),9),"Abrir WhatsApp")) -> Abrir WhatsApp | AM4: A página da escola liga a https://softdrive.me/#/horario/154 (horários; 154 = n.º IMT da escola) e ao e-learning https://ensinoadistancia.segurancarodoviaria.pt | AN4: Avenida dos Bombeiros Voluntários, nº 65 - 1º, 2580-289 Alenquer | AO4: https://www.segurancamaxima.pt/escolas-de-conducao/escola-de-conducao-de-alenquer/; https://escola-de-conducao.pt/escola-de-conducao-seguranca-maxima-de-alenquer-lda-306155.html; https://passaprimeira.xyz/distritos-regioes/lisboa/concelhos/alenquer/escolas/; https://www.imt-ip.pt/wp-content/uploads/2025/01/EscolasdeConducao-2021.pdf
A5: 4 | B5: A | C5: 10.1 | D5: Novo | E5: Pedro | F5: grupo | G5: Lisboa | H5: Alenquer | I5: Carregado | J5: Escola de Condução do Carregado (Segurança Máxima) | K5: Segurança Máxima (~70 escolas) | N5: 263 098 404 | O5: 918 210 710 | Q5: carregado@segurancamaxima.pt | R5: https://www.segurancamaxima.pt/escolas-de-conducao/escola-de-conducao-do-carregado/ | S5: https://www.facebook.com/grupo.seguranca.maxima | T5: https://www.instagram.com/seguranca.maxima/ | U5: 3.2 | V5: 33 | W5: Softdrive (gestão/horários) + e-learning do grupo | X5: Secretaria/telefone; reviews relatam meses sem conseguir marcar aulas práticas | Y5: Sim | Z5: Secretaria dias úteis 09h-20h, Sábado 09h-13h; aulas de condução Sábado 07h-13h (ABERTO sábado de manhã) | AA5: 646 | AB5: AM, A1, A2, A, B, B1, B+E, C, C1, C+E, D, D1, D+E | AC5: 'estou a 3 meses tentando marcar minhas aulas de condução e a resposta é sempre a mesma, “esse mês está cheio”' (Google, 2022); 'muito desorganizada e não tem professores que sejam suficiente para atender o número grande de alunos' (Google, 2022); 'Não atendem os telefones, nem email' (Google, 2021) - https://escola-de-conducao.pt/escola-de-conducao-maxima-carregado-306104.html; Queixa 2025: informação errada da secretaria sobre licença de aprendizagem - https://portaldaqueixa.com/brands/seguranca-maxima-escolas-de-conducao/complaints/seguranca-maxima-escolas-de-conducao-a-escola-seguranca-maxima-do-carregado-engana-os-alunos-para-ganhar-dinheiro-e-age-de-formas-ilegais-139435325 | AD5: Dor forte e recorrente em marcação de aulas/comunicação + volume alto (646); grupo grande já com Softdrive (decisão em Lisboa) | AH5: 0 | AL5: =IF(IF(O5<>"",O5,IF(LEFT(TRIM(N5),1)="9",N5,""))="","",HYPERLINK("https://wa.me/351"&LEFT(SUBSTITUTE(SUBSTITUTE(SUBSTITUTE(IF(O5<>"",O5,IF(LEFT(TRIM(N5),1)="9",N5,""))," ",""),"+351",""),"-",""),9),"Abrir WhatsApp")) -> Abrir WhatsApp | AM5: A página da escola liga a https://softdrive.me/#/horario/832 (horários; 832 = n.º IMT) e ao e-learning https://ensinoadistancia.segurancarodoviaria.pt | AN5: Rua Vaz Monteiro, Lote 33 R/C (Loja D), 2580-505 Carregado | AO5: https://www.segurancamaxima.pt/escolas-de-conducao/escola-de-conducao-do-carregado/; https://escola-de-conducao.pt/escola-de-conducao-maxima-carregado-306104.html; https://www.imt-ip.pt/wp-content/uploads/2025/01/EscolasdeConducao-2021.pdf; https://passaprimeira.xyz/distritos-regioes/lisboa/concelhos/alenquer/escolas/
A6: 5 | B6: A | C6: 9.5 | D6: Novo | E6: Pedro | F6: grupo | G6: Coimbra | H6: Coimbra | I6: Coimbra (Santa Clara) | J6: Escola de Condução Santa Clara | K6: Grupo MGA (Escolas MGA, desde 1971) - 5 escolas no distrito | N6: 239 404 497 | O6: 961 448 305 | Q6: geral@escolasmga.pt | R6: https://escolasmga.pt/escolas-de-conducao/coimbra-santa-clara/ | S6: https://www.facebook.com/escolasgrupomga | U6: 3.7 | V6: 27 | W6: BDrive | X6: Secretaria/telefone; BDrive para alunos registados (funcionalidades não detalhadas no site) | Y6: Não | Z6: Seg-Sex 09:00-12:00 / 14:00-19:00; Sábado encerrado (segundo listagem Google) | AA6: 979 | AB6: A, A1, A2, B1, B, B automático, BE, C, C1, CE, D, D1, DE, T, veículos adaptados; CAM | AC6: 'Têm um plano mensal de aulas presenciais marcado, pois chega-se a hora da aula, não aparece ninguém para dar aula' (https://escola-de-conducao.pt/escola-de-conducao-santa-clara-grupo-mga-desde-1971-305927.html); 'O plano de aulas teóricas previamente afixado não é cumprido!' (mesma fonte) | AD6: Grupo multi-escola (5 sites MGA no distrito), maior volume do grupo (979 provas 2021), queixas de aulas não cumpridas/comunicação; usa BDrive mas sem app próprio de marcação | AH6: 0 | AL6: =IF(IF(O6<>"",O6,IF(LEFT(TRIM(N6),1)="9",N6,""))="","",HYPERLINK("https://wa.me/351"&LEFT(SUBSTITUTE(SUBSTITUTE(SUBSTITUTE(IF(O6<>"",O6,IF(LEFT(TRIM(N6),1)="9",N6,""))," ",""),"+351",""),"-",""),9),"Abrir WhatsApp")) -> Abrir WhatsApp | AM6: https://escolasmga.pt/servicos/plataforma-bdrive/ (link para bdrive.pt, 'Acesso exclusivo a instruendos registados'); também 'Plataforma de Testes' e 'Pré-inscrição Online' | AN6: Rua Dr. Paulo Quintela, 23, 3030-393 Coimbra | AO6: https://escolasmga.pt/escolas-de-conducao/; https://escola-de-conducao.pt/escola-de-conducao-santa-clara-grupo-mga-desde-1971-305927.html; https://www.bomcondutor.pt/escolas/escola/santa-clara; https://www.andardemoto.pt/escolas-de-conducao/dir/d/coimbra/c/coimbra/p-2532/escola-de-conducao-santa-clara/; https://www.imt-ip.pt/wp-content/uploads/2025/01/EscolasdeConducao-2021.pdf
A7: 6 | B7: A | C7: 8.8 | D7: Novo | E7: Pedro | F7: grupo | G7: Santarém | H7: Santarém | I7: Santarém | J7: Escola de Condução Scallabis | K7: Grupo Caldas (11 escolas: Caldas, Louzan, Lizauto, Cardal, Via Maior, Capas Negras, Supertubos, Fica, Nova Setúbal, Scallabis, Nova Viseu) | O7: 910 403 321 | P7: yes | Q7: scallabis@grupocaldas.pt | R7: https://grupocaldas.pt/site/ecscallabis/ | S7: https://www.facebook.com/scallabis/ ; https://www.facebook.com/GrupoCaldasEC | T7: https://www.instagram.com/grupocaldas/ | U7: 2.6 | V7: 32 | X7: Telefone/WhatsApp e presencial (secretaria); calendário de teóricas em PDF | Y7: Sim | Z7: Secretaria: Seg-Sex 10:00-12:30 e 14:00-20:00; Sábado 09:00-13:00 (ABERTO SÁBADO) | AA7: 462 | AB7: A1, A2, A, B | AC7: 'A dificuldade que se tem para marcar (porque desmarcam 70% das vezes e sem avisar)' — https://escola-de-conducao.pt/escola-de-conducao-scallabis-306353.html; 'Tinha aulas de condução de 15 em 15 dias... cerca de 2 anos para concluir a carta' — idem; 'A escola não dá resposta aos pedidos de aulas de condução, o contacto telefónico... não teve qualquer resposta' — idem; 'Staff insuficiente' — idem; 'Nem sequer dão as aulas aos alunos! ... não conseguem marcar as aulas de condução' (Portal da Queixa, set 2023; índice de satisfação 13.9/100) — https://portaldaqueixa.com/brands/escola-de-conducao-scallabis | AD7: Grupo multi-escola (11 escolas, Grupo Caldas) + fortes queixas sobre marcação/desmarcação de aulas e falta de resposta; sem app próprio. Decisão provavelmente na sede (Caldas da Rainha, 262 877 371, info@eccaldas.pt) | AH7: 0 | AL7: =IF(IF(O7<>"",O7,IF(LEFT(TRIM(N7),1)="9",N7,""))="","",HYPERLINK("https://wa.me/351"&LEFT(SUBSTITUTE(SUBSTITUTE(SUBSTITUTE(IF(O7<>"",O7,IF(LEFT(TRIM(N7),1)="9",N7,""))," ",""),"+351",""),"-",""),9),"Abrir WhatsApp")) -> Abrir WhatsApp | AM7: Site do grupo só tem formulário de pré-inscrição, botão WhatsApp e PDF mensal 'Calendário de Aulas Teóricas' — sem área do aluno nem app | AN7: Av. Madre Andaluz 2A, 2000-210 Santarém | AO7: https://grupocaldas.pt/site/ecscallabis/; https://grupocaldas.pt/site/contactos/; https://escola-de-conducao.pt/escola-de-conducao-scallabis-306353.html; https://portaldaqueixa.com/brands/escola-de-conducao-scallabis; https://www.imt-ip.pt/wp-content/uploads/2025/01/EscolasdeConducao-2021.pdf
A8: 7 | B8: A | C8: 8.3 | D8: Novo | E8: Pedro | F8: grupo | G8: Leiria | H8: Batalha | I8: Golpilheira (Mouratos) | J8: Escola de Condução Batalhense - Batalha (sede) | K8: Grupo Batalhense | N8: 244 767 043 | O8: 917 073 335 | Q8: batalha@batalhense.com | R8: https://batalhense.com/escolas/escola-de-conducao-batalhense-batalha/ | S8: https://www.facebook.com/grupobatalhense | T8: https://www.instagram.com/batalhensegrupo/ | U8: 4.1 | V8: 23 | X8: Telefone/secretaria presencial; formulário de inscrição no site | Y8: Sim | Z8: Secretaria 2ª-6ª 9h30-12h30 / 14h30-20h; Sábado 9h30-12h30 (ABERTO sábado) | AA8: 445 | AB8: A, B, C, D; CAM, TCC, curso de instrutores, carta inclusiva (veículo adaptado) | AC8: "Instrutora com muita amargura, pouco interesse, constantemente tarde para às aulas" (Google 1★, 01/2024) https://escola-de-conducao.pt/escola-de-conducao-batalhense-306367.html | AD8: SEDE do Grupo Batalhense (6 escolas, desde 1996, contacto geral 244 767 043) - decisor provável aqui; 445 exames 2021 | AH8: 0 | AL8: =IF(IF(O8<>"",O8,IF(LEFT(TRIM(N8),1)="9",N8,""))="","",HYPERLINK("https://wa.me/351"&LEFT(SUBSTITUTE(SUBSTITUTE(SUBSTITUTE(IF(O8<>"",O8,IF(LEFT(TRIM(N8),1)="9",N8,""))," ",""),"+351",""),"-",""),9),"Abrir WhatsApp")) -> Abrir WhatsApp | AM8: Sem área do aluno/app no site batalhense.com; só formulário de inscrição (contacto). Aulas de código online de apoio (3ª e 5ª). | AN8: R. Comendador Joaquim Sales, Mouratos, 42 - 2440-042 Batalha | AO8: https://passaprimeira.xyz/distritos-regioes/leiria/concelhos/batalha/escolas/batalhense-00588/; https://batalhense.com/; https://batalhense.com/escolas/escola-de-conducao-batalhense-batalha/; https://escola-de-conducao.pt/escola-de-conducao-batalhense-306367.html
A9: 8 | B9: A | C9: 8 | D9: Novo | E9: Pedro | F9: grupo | G9: Leiria | H9: Pombal | I9: Pombal | J9: Clube do Condutor (Escolas de Condução Esteves - Pombal) | K9: Escolas de Condução Esteves | N9: 236 023 907 | O9: 916 844 922 | Q9: clubedocondutor@gmail.com | R9: https://ec-esteves.pt/ | S9: https://www.facebook.com/escolaesteves | U9: 2.5 | V9: 2 | X9: Telefone/secretaria | Y9: Sim | Z9: Secretaria dias úteis 10h-12h / 14h30-19h30; Sábado 10h-12h (ABERTO sábado); aulas de condução sáb 8h-13h | AA9: 128 | AC9: "Não achei a professora prestativa em querer ensinar o aluno acabei desistindo" (Google 1★, 2022) https://escola-de-conducao.pt/escola-de-conducao-clube-do-condutor-306908.html | AD9: Grupo Esteves (3 escolas); 128 exames 2021 | AH9: 0 | AL9: =IF(IF(O9<>"",O9,IF(LEFT(TRIM(N9),1)="9",N9,""))="","",HYPERLINK("https://wa.me/351"&LEFT(SUBSTITUTE(SUBSTITUTE(SUBSTITUTE(IF(O9<>"",O9,IF(LEFT(TRIM(N9),1)="9",N9,""))," ",""),"+351",""),"-",""),9),"Abrir WhatsApp")) -> Abrir WhatsApp | AN9: R. Albergaria dos Doze, 55/57 - 3100-456 Pombal | AO9: https://passaprimeira.xyz/distritos-regioes/leiria/concelhos/pombal/escolas/clube-do-condutor-01370/; https://ec-esteves.pt/contactos/; https://ec-esteves.pt/horarios/; https://escola-de-conducao.pt/escola-de-conducao-clube-do-condutor-306908.html
A10: 9 | B10: A | C10: 7.8 | D10: Novo | E10: Pedro | F10: grupo | G10: Leiria | H10: Pombal | I10: Pombal | J10: Escola de Condução Batalhense - Pombal (Triangular) | K10: Grupo Batalhense | N10: 236 218 033 | O10: 919 868 022 | Q10: triangular@batalhense.com | R10: https://batalhense.com/escolas/escola-de-conducao-batalhense-pombal-triangular/ | S10: https://www.facebook.com/grupobatalhense | T10: https://www.instagram.com/batalhensegrupo/ | U10: 4.2 | V10: 10 | X10: Telefone/secretaria presencial; formulário de inscrição no site | Y10: Sim | Z10: Secretaria 2ª-6ª 9h30-12h30 / 14h30-19h30; Sábado 9h30-12h30 (ABERTO sábado) | AA10: 314 | AB10: A, B, C, D (grupo) | AC10: "Minha experiência no atendimento não foi dos melhores... não foi passado a informação que desejava" (Google 1★, 01/2023) https://escola-de-conducao.pt/escola-de-conducao-automovel-triangular-lda-306649.html | AD10: Grupo Batalhense + queixas de atendimento; 314 exames 2021 | AH10: 0 | AL10: =IF(IF(O10<>"",O10,IF(LEFT(TRIM(N10),1)="9",N10,""))="","",HYPERLINK("https://wa.me/351"&LEFT(SUBSTITUTE(SUBSTITUTE(SUBSTITUTE(IF(O10<>"",O10,IF(LEFT(TRIM(N10),1)="9",N10,""))," ",""),"+351",""),"-",""),9),"Abrir WhatsApp")) -> Abrir WhatsApp | AM10: Sem área do aluno/app no site batalhense.com; só formulário de inscrição (contacto). Aulas de código online de apoio (3ª e 5ª). | AN10: Av. Arquitecto Rosado Correia 3 - 3100-430 Pombal | AO10: https://passaprimeira.xyz/distritos-regioes/leiria/concelhos/pombal/escolas/triangular-00537/; https://batalhense.com/; https://batalhense.com/escolas/escola-de-conducao-batalhense-pombal-triangular/; https://escola-de-conducao.pt/escola-de-conducao-automovel-triangular-lda-306649.html
A11: 10 | B11: A | C11: 7.8 | D11: Novo | E11: Pedro | F11: grupo | G11: Leiria | H11: Figueiró dos Vinhos | I11: Figueiró dos Vinhos | J11: Escola de Condução Lago Azul - Figueiró dos Vinhos | K11: Lago Azul (grupo, segundo bomcondutor) | N11: 236 551 611 | S11: https://www.facebook.com/ECLagoAzul | U11: 3.3 | V11: 3 | AA11: 86 | AC11: "eu tinha de pedir se faz favor para me ajudar e explicar melhor!! fiquei traumatizado com esta escola" (Google 1★, 03/2024) https://escola-de-conducao.pt/escola-de-conducao-lago-azul-lda-307080.html | AD11: Delegação de grupo (Lago Azul) + queixa recente; volume baixo (86 exames 2021) | AH11: 0 | AL11: =IF(IF(O11<>"",O11,IF(LEFT(TRIM(N11),1)="9",N11,""))="","",HYPERLINK("https://wa.me/351"&LEFT(SUBSTITUTE(SUBSTITUTE(SUBSTITUTE(IF(O11<>"",O11,IF(LEFT(TRIM(N11),1)="9",N11,""))," ",""),"+351",""),"-",""),9),"Abrir WhatsApp")) | AN11: Av. Dr. Francisco Sá Carneiro - 3260-400 Figueiró dos Vinhos | AO11: https://passaprimeira.xyz/distritos-regioes/leiria/concelhos/figueiro-dos-vinhos/escolas/lago-azul-figueiro-dos-vinhos-00491/; https://escola-de-conducao.pt/escola-de-conducao-lago-azul-lda-307080.html; https://www.bomcondutor.pt/escolas/escola/lago-azul-figueiro-dos-vinhos
A12: 11 | B12: A | C12: 7.6 | D12: Novo | E12: Pedro | F12: grupo | G12: Leiria | H12: Leiria | I12: Leiria (Nova Leiria) | J12: Escola de Condução Batalhense - Leiria (Nova Leiria) | K12: Grupo Batalhense | N12: 244 802 890 | O12: 918 782 380 | Q12: leiria@batalhense.com | R12: https://batalhense.com/escolas/escola-de-conducao-batalhense-leiria-nova-leiria/ | S12: https://www.facebook.com/grupobatalhense | T12: https://www.instagram.com/batalhensegrupo/ | U12: 4.4 | V12: 19 | X12: Telefone/secretaria presencial; formulário de inscrição no site | Y12: Sim | Z12: Secretaria 2ª-6ª 9h30-12h30 / 14h30-19h30; Sábado 10h-12h30 (ABERTO sábado de manhã) | AA12: 535 | AB12: A, B, C, D (grupo); CAM, TCC, curso de instrutores | AC12: "A escola nada responde e pelos vistos pouco se importa" (Google, 1★, 2022) https://escola-de-conducao.pt/escola-de-conducao-batalhense-de-leiria-306236.html | AD12: Grupo multi-escola (6 escolas no distrito: Leiria x2, Batalha, Marinha Grande, Alcobaça, Pombal); maior volume do grupo (535 exames 2021); sem app de aluno | AH12: 0 | AL12: =IF(IF(O12<>"",O12,IF(LEFT(TRIM(N12),1)="9",N12,""))="","",HYPERLINK("https://wa.me/351"&LEFT(SUBSTITUTE(SUBSTITUTE(SUBSTITUTE(IF(O12<>"",O12,IF(LEFT(TRIM(N12),1)="9",N12,""))," ",""),"+351",""),"-",""),9),"Abrir WhatsApp")) -> Abrir WhatsApp | AM12: Sem área do aluno/app no site batalhense.com; só formulário de inscrição (contacto). Aulas de código online de apoio (3ª e 5ª). | AN12: Av. Doutor Adelino Amaro da Costa, 2 - 2415-367 Leiria | AO12: https://passaprimeira.xyz/distritos-regioes/leiria/concelhos/leiria/escolas/batalhense-de-leiria-00872/; https://batalhense.com/; https://batalhense.com/escolas/escola-de-conducao-batalhense-leiria-nova-leiria/; https://escola-de-conducao.pt/escola-de-conducao-batalhense-de-leiria-306236.html; https://www.andardemoto.pt/escolas-de-conducao/dir/d/leiria/c/leiria/p-2191/batalhense-de-leiria/
A13: 12 | B13: A | C13: 7.5 | D13: Novo | E13: Pedro | F13: grupo | G13: Aveiro | H13: Aveiro | I13: Aveiro (centro) | J13: Escola de Condução Nova de Aveiro (Bordalo Pinheiro) | K13: Grupo Bordalo | N13: 234 025 683; 234 420 893 | S13: https://www.facebook.com/pages/Escola-de-condu%C3%A7%C3%A3o-Bordalo-Pinheiro/127727473957013 | U13: 2.8 | V13: 33 | X13: Não divulgado online (sem plataforma de marcação visível) | Y13: Sim | Z13: Seg-Sex 10:00-12:30 e 14:00-20:00; Sábado 10:00-12:30 (aberto ao sábado de manhã) | AA13: 378 | AC13: "desmarcam aulas à última da hora"; "ser do conhecimento da secretaria que o instrutor não poderia comparecer a uma aula e não me informarem" (10/2023); "A escola tem poucas aulas e poucos horários difíceis de frequentar"; "vai adiando no tempo as aulas e os pedidos de exames" (08/2023); "Recepção ruim. Não fornece informações" (01/2024) — https://escola-de-conducao.pt/nova-de-aveiro-escola-de-conducao-306455.html | AD13: Grupo Bordalo (multi-escola: Nova de Aveiro, Rainha de Aveiro, Águeda); 2.º maior volume do concelho; dor explícita com desmarcações e falta de comunicação — encaixe direto com notificações push | AH13: 0 | AL13: =IF(IF(O13<>"",O13,IF(LEFT(TRIM(N13),1)="9",N13,""))="","",HYPERLINK("https://wa.me/351"&LEFT(SUBSTITUTE(SUBSTITUTE(SUBSTITUTE(IF(O13<>"",O13,IF(LEFT(TRIM(N13),1)="9",N13,""))," ",""),"+351",""),"-",""),9),"Abrir WhatsApp")) | AN13: Av. 5 de Outubro, n.º 21, R/C Dt.º, 3800-428 Aveiro (Google: R. Cmte. Rocha e Cunha 3, 3800-126) | AO13: https://www.bomcondutor.pt/escolas/escola/bordalo-pinheiro-nova-de-aveiro; https://escola-de-conducao.pt/nova-de-aveiro-escola-de-conducao-306455.html (rating Google via snapshot escola-de-conducao.pt); https://passaprimeira.xyz/en/districts-regions/aveiro/municipalities/aveiro/schools/; https://transitoagora.pt/escolas-conducao/aveiro
A14: 13 | B14: A | C14: 7.4 | D14: Novo | E14: Pedro | F14: grupo | G14: Santarém | H14: Ferreira do Zêzere | I14: Ferreira do Zêzere | J14: Escola de Condução Lago Azul (alvará 'Ferreira do Zêzere') | K14: Lago Azul (Ferreira do Zêzere + Figueiró dos Vinhos) | N14: 249 361 434 | O14: 912 231 788 | U14: 3.3 | V14: 6 | X14: Presencial/telefone | Y14: Sim | Z14: Seg-Sex 09:00-13:00 e 15:00-20:00; Sábado 09:00-13:00 (ABERTO sábado) | AA14: 98 | AB14: A, B, C, D, E; CAM, ADR | AC14: 'Fiquei muito desagradado com o não cumprimento do horário... nem sequer dado qualquer satisfação' (1/5, 2023, consulta médica na escola) - https://escola-de-conducao.pt/escola-de-conducao-lago-azul-lda-253847.html; 'Não recomendo!' (1/5, 2024) - mesma fonte | AD14: Grupo multi-site (Ferreira do Zêzere + Figueiró dos Vinhos, este com 86 exames 2021), todas as categorias, queixas de falta de comunicação/horários; rating 3.3. Exames 2021 = entrada IMT 'Ferreira do Zêzere' (mesmo telefone/morada histórica). | AH14: 0 | AL14: =IF(IF(O14<>"",O14,IF(LEFT(TRIM(N14),1)="9",N14,""))="","",HYPERLINK("https://wa.me/351"&LEFT(SUBSTITUTE(SUBSTITUTE(SUBSTITUTE(IF(O14<>"",O14,IF(LEFT(TRIM(N14),1)="9",N14,""))," ",""),"+351",""),"-",""),9),"Abrir WhatsApp")) -> Abrir WhatsApp | AM14: Uma avaliação refere 'Plataformas de estudo Online e Aplicações para estudar' (e-learning de código, não marcação) | AN14: Rua Dr. Francisco Sá Carneiro, 30, 2240-353 Ferreira do Zêzere (antes Urb. Quinta do Adro) | AO14: https://escola-de-conducao.pt/escola-de-conducao-lago-azul-lda-253847.html; https://www.racius.com/escola-de-conducao-lago-azul-lda/; https://www.testesdecodigogratis.com/escola-de-conducao/lago-azul-ferreira-do-zezere/; https://www.andardemoto.pt/escolas-de-conducao/dir/d/santarem/c/ferreira-do-zezere/p-2954/escola-de-conducao-quinta-do-adro/; https://www.imt-ip.pt/wp-content/uploads/2025/01/EscolasdeConducao-2021.pdf
A15: 14 | B15: A | C15: 7.2 | D15: Novo | E15: Pedro | F15: grupo | G15: Santarém | H15: Almeirim | I15: Almeirim | J15: Escola de Condução Jorge Justino - Almeirim | K15: Escolas de Condução Matos (família Tomé; antigo site matosconducao.com, inativo) | N15: 243 591 755 ; 243 593 590 | O15: 934 100 817 | AA15: 672 | AD15: Maior volume da zona (672 provas em 2021) e parte do grupo Matos; sem plataforma digital visível | AH15: 0 | AL15: =IF(IF(O15<>"",O15,IF(LEFT(TRIM(N15),1)="9",N15,""))="","",HYPERLINK("https://wa.me/351"&LEFT(SUBSTITUTE(SUBSTITUTE(SUBSTITUTE(IF(O15<>"",O15,IF(LEFT(TRIM(N15),1)="9",N15,""))," ",""),"+351",""),"-",""),9),"Abrir WhatsApp")) -> Abrir WhatsApp | AM15: Site do grupo matosconducao.com já não resolve (arquivo web 2013-2016 lista: Almeirim J. Justino, Almeirinense, Alpiarça, Azambuja, Cartaxo, Fazendas de Almeirim, Santarém Ribatejana, Pedro de Santarém) — https://web.archive.org/web/2013/http://www.matosconducao.com/matos/4567579683; nenhum portal do aluno visível | AN15: Av. 25 de Abril, Bloco D (Edifício Sintra de Inverno, r/c), 2080-012 Almeirim | AO15: https://www.testesdecodigogratis.com/escola-de-conducao/jorge-justino/; https://escolasconducao.com/escola/escola-de-conducao-jorge-justino-lda; https://www.imt-ip.pt/wp-content/uploads/2025/01/EscolasdeConducao-2021.pdf
A16: 15 | B16: A | C16: 7.1 | D16: Novo | E16: Pedro | F16: grupo | G16: Santarém | H16: Benavente | I16: Benavente | J16: Escola de Condução Nossa Senhora da Paz | K16: Nossa Senhora da Paz (Benavente, Cartaxo, Santarém) | N16: 263 517 675 | O16: 919 171 910 | P16: yes | Q16: geral@escolaconducao.pt | R16: https://www.escolaconducao.pt/ | S16: https://www.facebook.com/EscolaDeConducaoNossaSraDaPaz/ | T16: https://www.instagram.com/escolaconducaonsrapaz/ | X16: Telefone/WhatsApp e formulário de contacto; aulas técnicas 'em conformidade com a disponibilidade do instruendo/instrutor'; sem marcação online | Y16: Sim | Z16: Secretaria: Seg-Sex 09:30-12:30 / 14:30-19:30 (sábado não indicado); aulas práticas 08:30-19:30 | AA16: 524 | AB16: AM, A1, A2, A, B1, B, B+E, C1, C, C+E, D, T3 (mais cursos CAM, TCC, ADR, tacógrafos) | AC16: 'ter que esperar 30 min pra ser atendido, e em dia de consulta marcada pode esperar até 1 hora' / 'nas aulas de condução fazem sempre o mesmo percurso' (nov. 2022) https://portaldaqueixa.com/brands/escola-de-conducao-nossa-senhora-da-paz/complaints/escola-de-conducao-nossa-senhora-da-paz-pior-escola-de-conducao-do-pais-82918222; queixa sobre chumbos e comunicação com a instrutora (jul. 2020) https://portaldaqueixa.com/brands/escola-de-conducao-nossa-senhora-da-paz/complaints/escola-de-conducao-nossa-senhora-da-paz-quero-que-seja-averiguado-o-motivo-de-tanto-chumbo-nesta-escola-43513520 | AD16: Grupo com 3 escolas, todas as categorias, volume alto (524 provas em 2021), presença digital ativa e queixas no Portal da Queixa sobre esperas no atendimento | AH16: 0 | AL16: =IF(IF(O16<>"",O16,IF(LEFT(TRIM(N16),1)="9",N16,""))="","",HYPERLINK("https://wa.me/351"&LEFT(SUBSTITUTE(SUBSTITUTE(SUBSTITUTE(IF(O16<>"",O16,IF(LEFT(TRIM(N16),1)="9",N16,""))," ",""),"+351",""),"-",""),9),"Abrir WhatsApp")) -> Abrir WhatsApp | AM16: O site tem plataforma de testes online para alunos (link para pugnatrix.com/proexamweb) e anuncia e-learning de código; não se identificou AGEOnline/BDrive/ALSIS. Também tem TikTok @escola.nossasradapaz | AN16: Rua Joaquim Rodrigues Parracho, Lote 25 R/C Dto, 2130-060 Benavente | AO16: https://www.escolaconducao.pt/; https://www.escolaconducao.pt/escola.html; https://www.escolaconducao.pt/contactos.html; https://www.escolaconducao.pt/cartas.html; https://www.bomcondutor.pt/escolas/escola/nossa-senhora-da-paz; https://portaldaqueixa.com/brands/escola-de-conducao-nossa-senhora-da-paz/complaints; https://www.imt-ip.pt/wp-content/uploads/2025/01/EscolasdeConducao-2021.pdf
A17: 16 | B17: A | C17: 7 | D17: Novo | E17: Pedro | F17: grupo | G17: Leiria | H17: Leiria | I17: Leiria (Guimarota) | J17: Escola de Condução Rota do Sol - Leiria | K17: Rota do Sol | N17: 244 828 600 | Q17: escola@rotadosol.pt | R17: http://www.rotadosol.pt/ | S17: https://www.facebook.com/escolarotadosol | U17: 5 | V17: 240 | X17: Telefone/presencial (reviews elogiam flexibilidade de horários ajustados pela secretaria) | Y17: Sim | Z17: 2ª-6ª 10h-13h / 15h-18h30; Sábado 10h-13h (ABERTO sábado, segundo Google) | AA17: 498 | AD17: 2 escolas (Leiria + Caranguejeira); 498 exames 2021; muito ativa em reviews (240, 5.0); site obsoleto, sem app | AH17: 0 | AL17: =IF(IF(O17<>"",O17,IF(LEFT(TRIM(N17),1)="9",N17,""))="","",HYPERLINK("https://wa.me/351"&LEFT(SUBSTITUTE(SUBSTITUTE(SUBSTITUTE(IF(O17<>"",O17,IF(LEFT(TRIM(N17),1)="9",N17,""))," ",""),"+351",""),"-",""),9),"Abrir WhatsApp")) | AM17: Site rotadosol.pt desatualizado (2012), sem área do aluno | AN17: Praceta Cristiano Schurmann, 55 - 2410-380 Leiria (Guimarota) | AO17: https://passaprimeira.xyz/distritos-regioes/leiria/concelhos/leiria/escolas/rota-do-sol-00695/; https://escola-de-conducao.pt/escola-de-conducao-rota-do-sol-leiria-306233.html; https://www.bomcondutor.pt/escolas/escola/rota-do-sol-leiria; https://www.andardemoto.pt/escolas-de-conducao/dir/d/leiria/c/leiria/p-2983/escola-de-conducao-rota-do-sol/
A18: 17 | B18: A | C18: 7 | D18: Novo | E18: Pedro | F18: grupo | G18: Lisboa | H18: Alenquer | I18: Alenquer | J18: Escola de Condução Nova Paredes (MegaDriving) | K18: MegaDriving | N18: 263 738 183 | O18: 966 216 719 | Q18: novaparedes.ec@gmail.com | R18: https://www.megadriving.com.pt/ec_novaparedes.php | S18: https://www.facebook.com/p/Escola-de-Condu%C3%A7%C3%A3o-Nova-Paredes-100057583264805/ | U18: 4.5 | V18: 4 | X18: Presencial/telefone; sem marcação online visível | Y18: Sim | Z18: Secretaria 2ª-6ª 10h-13h e 15h-20h; Sábado 10h-13h (ABERTO sábado de manhã; Google indica sábado 09h-13h) | AA18: 495 | AD18: Grupo MegaDriving + volume alto (495 provas 2021). Ocupa a morada da antiga 'Bordalo - Alão' listada no bomcondutor (dados desatualizados) | AH18: 0 | AL18: =IF(IF(O18<>"",O18,IF(LEFT(TRIM(N18),1)="9",N18,""))="","",HYPERLINK("https://wa.me/351"&LEFT(SUBSTITUTE(SUBSTITUTE(SUBSTITUTE(IF(O18<>"",O18,IF(LEFT(TRIM(N18),1)="9",N18,""))," ",""),"+351",""),"-",""),9),"Abrir WhatsApp")) -> Abrir WhatsApp | AM18: Site do grupo (megadriving.com.pt) só tem formulário de contacto e página de inscrição; sem área do aluno nem links para AGEOnline/BDrive/ALSIS | AN18: Rua Jorge Cunha e Carmo, Lt 35 R/C Direito, 2580-531 Alenquer | AO18: https://www.megadriving.com.pt/ec_novaparedes.php; https://passaprimeira.xyz/distritos-regioes/lisboa/concelhos/alenquer/escolas/; https://www.imt-ip.pt/wp-content/uploads/2025/01/EscolasdeConducao-2021.pdf; https://escola-de-conducao.pt/escola-de-conducao-nova-paredes-306473.html; https://www.bomcondutor.pt/escolas/escola/bordalo-alao
A19: 18 | B19: A | C19: 6.9 | D19: Novo | E19: Pedro | F19: grupo | G19: Leiria | H19: Alcobaça | I19: Benedita | J19: Escola de Condução Beneditense | K19: Grupo Letra (inferido: mesmo telefone 262 929 464 e ficha Google liga a grupoletra.pt) | N19: 262 929 464 | R19: http://www.grupoletra.pt/ | S19: https://www.facebook.com/beneditense | U19: 4.8 | V19: 9 | AA19: 465 | AD19: Provável Grupo Letra; volume elevado (465 exames 2021) | AH19: 0 | AL19: =IF(IF(O19<>"",O19,IF(LEFT(TRIM(N19),1)="9",N19,""))="","",HYPERLINK("https://wa.me/351"&LEFT(SUBSTITUTE(SUBSTITUTE(SUBSTITUTE(IF(O19<>"",O19,IF(LEFT(TRIM(N19),1)="9",N19,""))," ",""),"+351",""),"-",""),9),"Abrir WhatsApp")) | AN19: Rua Padre Dr. Fernando Maurício, 2 r/c - 2475-138 Benedita | AO19: https://passaprimeira.xyz/distritos-regioes/leiria/concelhos/alcobaca/escolas/beneditense-00528/; https://escola-de-conducao.pt/escola-de-conducao-beneditense-lda-307165.html; https://www.bomcondutor.pt/escolas/escola/beneditense
A20: 19 | B20: A | C20: 6.9 | D20: Novo | E20: Pedro | F20: grupo | G20: Lisboa | H20: Sobral de Monte Agraço | I20: Sobral de Monte Agraço | J20: Escola de Condução Sobralense (Progresso Sobralense) | K20: Sobralense / Arrudense (provável: partilham o telefone 261 941 052) | N20: 261 941 293; 261 941 052 | O20: 964 648 572 | S20: https://www.facebook.com/Escola.Sobralense | U20: 4.5 | V20: 19 | X20: Presencial/telefone | Y20: Sim | Z20: 2ª-6ª 09h-13h e 15h-21h; Sábado 09h-13h (ABERTO sábado de manhã) - Google | AA20: 465 | AD20: Volume alto (465) + provável grupo com a Arrudense; sem app | AH20: 0 | AL20: =IF(IF(O20<>"",O20,IF(LEFT(TRIM(N20),1)="9",N20,""))="","",HYPERLINK("https://wa.me/351"&LEFT(SUBSTITUTE(SUBSTITUTE(SUBSTITUTE(IF(O20<>"",O20,IF(LEFT(TRIM(N20),1)="9",N20,""))," ",""),"+351",""),"-",""),9),"Abrir WhatsApp")) -> Abrir WhatsApp | AN20: Avenida Marquês de Pombal, nº 53 Loja Dta, 2590-041 Sobral de Monte Agraço | AO20: https://www.bomcondutor.pt/escolas/escola/sobralense; https://escola-de-conducao.pt/escola-de-conducao-sobralense-237628.html; https://www.imt-ip.pt/wp-content/uploads/2025/01/EscolasdeConducao-2021.pdf
A21: 20 | B21: A | C21: 6.9 | D21: Novo | E21: Pedro | F21: grupo | G21: Coimbra | H21: Oliveira do Hospital | I21: Oliveira do Hospital | J21: Escola de Condução Oliveirense (sede Grupo MGA) | K21: Grupo MGA (Escolas MGA, desde 1971) - 5 escolas no distrito | N21: 238 609 505 | O21: 961 448 303; 969 027 540 | Q21: geral@escolasmga.pt | R21: https://escolasmga.pt/escolas-de-conducao/oliveira-do-hospital-oliveirense/ | S21: https://www.facebook.com/escolasgrupomga | U21: 4.5 | V21: 46 | W21: BDrive | X21: Secretaria/telefone; BDrive para alunos registados; oferece 'Carta em 1 mês' com alojamento | Y21: Sim | Z21: Seg-Sex 09:00-12:00 / 14:00-19:00; Sábado 09:00-12:00 (aberto ao sábado) | AA21: 594 | AB21: A, A1, A2, B1, B, B automático, BE, C, C1, CE, D, D1, DE, T, veículos adaptados; CAM | AC21: 'Liguei para obter algumas informações ... o Dono desta escola me responde num tom rude' (2024, https://escola-de-conducao.pt/escola-de-conducao-mga-oliveirense-desde-1971-305796.html) | AD21: Sede do Grupo MGA (5 escolas no distrito) — decisor do grupo; 594 provas 2021 | AH21: 0 | AL21: =IF(IF(O21<>"",O21,IF(LEFT(TRIM(N21),1)="9",N21,""))="","",HYPERLINK("https://wa.me/351"&LEFT(SUBSTITUTE(SUBSTITUTE(SUBSTITUTE(IF(O21<>"",O21,IF(LEFT(TRIM(N21),1)="9",N21,""))," ",""),"+351",""),"-",""),9),"Abrir WhatsApp")) -> Abrir WhatsApp | AM21: https://escolasmga.pt/servicos/plataforma-bdrive/ (link para bdrive.pt, 'Acesso exclusivo a instruendos registados'); também 'Plataforma de Testes' e 'Pré-inscrição Online' | AN21: Av. Dr. Carlos Campos, Apartado 1, 3404-909 Oliveira do Hospital | AO21: https://escolasmga.pt/escolas-de-conducao/; https://escola-de-conducao.pt/escola-de-conducao-mga-oliveirense-desde-1971-305796.html; https://www.andardemoto.pt/escolas-de-conducao/dir/d/coimbra/c/oliveira-do-hospital/p-3313/oliveirense/; https://www.imt-ip.pt/wp-content/uploads/2025/01/EscolasdeConducao-2021.pdf
A22: 21 | B22: A | C22: 6.8 | D22: Novo | E22: Pedro | F22: grupo | G22: Santarém | H22: Santarém | I22: Santarém | J22: Escola de Condução Ribatejana (Tomé) | K22: Escolas de Condução Matos (família Tomé; antigo site matosconducao.com, inativo) | N22: 243 322 500 ; 243 328 512 | O22: 939 349 024 | Q22: ecribatejana@hotmail.com | X22: Telefone/presencial | AA22: 580 | AD22: Parte do grupo Matos; maior volume do grupo em Santarém (IMT 2021 'Escola de Condução Tomé' = mesma morada/telefone 243 328 512) | AH22: 0 | AL22: =IF(IF(O22<>"",O22,IF(LEFT(TRIM(N22),1)="9",N22,""))="","",HYPERLINK("https://wa.me/351"&LEFT(SUBSTITUTE(SUBSTITUTE(SUBSTITUTE(IF(O22<>"",O22,IF(LEFT(TRIM(N22),1)="9",N22,""))," ",""),"+351",""),"-",""),9),"Abrir WhatsApp")) -> Abrir WhatsApp | AM22: Site do grupo matosconducao.com já não resolve (arquivo web 2013-2016 lista: Almeirim J. Justino, Almeirinense, Alpiarça, Azambuja, Cartaxo, Fazendas de Almeirim, Santarém Ribatejana, Pedro de Santarém) — https://web.archive.org/web/2013/http://www.matosconducao.com/matos/4567579683; nenhum portal do aluno visível | AN22: Largo Infante Santo nº 4, 1º Esq., 2005-246 Santarém | AO22: https://www.andardemoto.pt/escolas-de-conducao/dir/d/santarem/c/santarem/p-2964/escola-de-conducao-ribatejana/; https://www.testesdecodigogratis.com/escola-de-conducao/ribatejana/; https://www.municipiosefreguesias.pt/entidade/166988/escola-de-conducao-tome--santarem; https://www.imt-ip.pt/wp-content/uploads/2025/01/EscolasdeConducao-2021.pdf
A23: 22 | B23: A | C23: 6.7 | D23: Novo | E23: Pedro | F23: grupo | G23: Leiria | H23: Marinha Grande | I23: Marinha Grande | J23: Escola de Condução Batalhense - Marinha Grande | K23: Grupo Batalhense | N23: 244 569 430 | O23: 918 782 381 | Q23: marinha@batalhense.com | R23: https://batalhense.com/escolas/escola-de-conducao-batalhense-marinha-grande/ | S23: https://www.facebook.com/grupobatalhense | T23: https://www.instagram.com/batalhensegrupo/ | X23: Telefone/secretaria presencial; formulário de inscrição no site | Y23: Não | Z23: Secretaria 2ª-6ª 9h30-12h30 / 14h30-19h30; sábado não indicado no site (provavelmente fechado) | AA23: 426 | AB23: A, B, C, D (grupo) | AD23: Grupo Batalhense (multi-escola); 426 exames 2021 | AH23: 0 | AL23: =IF(IF(O23<>"",O23,IF(LEFT(TRIM(N23),1)="9",N23,""))="","",HYPERLINK("https://wa.me/351"&LEFT(SUBSTITUTE(SUBSTITUTE(SUBSTITUTE(IF(O23<>"",O23,IF(LEFT(TRIM(N23),1)="9",N23,""))," ",""),"+351",""),"-",""),9),"Abrir WhatsApp")) -> Abrir WhatsApp | AM23: Sem área do aluno/app no site batalhense.com; só formulário de inscrição (contacto). Aulas de código online de apoio (3ª e 5ª). | AN23: R. Alfredo Gândara, 22 - 2430-300 Marinha Grande | AO23: https://passaprimeira.xyz/distritos-regioes/leiria/concelhos/marinha-grande/escolas/batalhense-da-marinha-grande-00855/; https://batalhense.com/; https://batalhense.com/escolas/escola-de-conducao-batalhense-marinha-grande/
A24: 23 | B24: A | C24: 6.6 | D24: Novo | E24: Pedro | F24: grupo | G24: Leiria | H24: Alcobaça | I24: Alcobaça | J24: Escola de Condução Alcobacense | K24: Grupo Letra | N24: 262 929 464 | Q24: geral.alcobacense@gmail.com / esc.alcobacense@gmail.com | R24: https://www.alcobacense.com/ | S24: https://www.facebook.com/escconducaoalcobacense/ | T24: https://www.instagram.com/esc_alcobacense/ | U24: 4.9 | V24: 8 | X24: Telefone/presencial; inscrição por formulário no site | Y24: Sim | Z24: 2ª-6ª 9h-13h / 14h30-18h30; Sábado 10h-12h (sob consulta) | AA24: 412 | AB24: AM, A1, A2, A, B, B+E, condução com tutor, pesados; CAM, TVDE | AD24: Grupo Letra (Alcobacense + Beneditense + Motoschool + centro de formação); 412 exames 2021 | AH24: 0 | AL24: =IF(IF(O24<>"",O24,IF(LEFT(TRIM(N24),1)="9",N24,""))="","",HYPERLINK("https://wa.me/351"&LEFT(SUBSTITUTE(SUBSTITUTE(SUBSTITUTE(IF(O24<>"",O24,IF(LEFT(TRIM(N24),1)="9",N24,""))," ",""),"+351",""),"-",""),9),"Abrir WhatsApp")) | AM24: Site Webnode com páginas "Mapa de Aulas", "Ensino à Distância" e "Testes de Código" (sem área do aluno/app de marcação) | AN24: Rua Luís de Camões, 67 Lote A R/C - 2460-014 Alcobaça | AO24: https://passaprimeira.xyz/distritos-regioes/leiria/concelhos/alcobaca/escolas/alcobacense-00179/; https://grupoletra.pt/alcobacense/; https://grupoletra.pt/contacto/; https://www.alcobacense.com/; https://escola-de-conducao.pt/escola-de-conducao-alcobacense-306702.html
A25: 24 | B25: A | C25: 6.6 | D25: Novo | E25: Pedro | F25: grupo | G25: Santarém | H25: Ourém | I25: Ourém | J25: Escola de Condução Ouriense | K25: Espada & Oliveira (Ouriense, Fatimense, Caxariense) | N25: 249 545 208 | O25: 919 537 599 / 933 890 089 / 933 885 930 | Q25: ec-ouriense@espadaeoliveira.com | R25: https://www.espadaeoliveira.pt/ouriense.php | S25: https://www.facebook.com/pages/ESCOLA-DE-CONDU%C3%87%C3%83O-OURIENSE/117550408321810 | U25: 4.2 | V25: 6 | X25: Telefone/presencial; pré-inscrição por formulário no site | Y25: Sim | Z25: Seg-Sex 09:00-12:30 e 14:30-19:30; Sábado 09:00-12:00 (ABERTO sábado) | AA25: 524 | AB25: Todas as categorias (A, B, C, D, E); CAM, TCC, tacógrafos | AD25: Sede de um grupo com 3 escolas (Ourém, Fátima, Caxarias), alvará desde 1956, 524 exames 2021, também centro de formação CAM. | AH25: 0 | AL25: =IF(IF(O25<>"",O25,IF(LEFT(TRIM(N25),1)="9",N25,""))="","",HYPERLINK("https://wa.me/351"&LEFT(SUBSTITUTE(SUBSTITUTE(SUBSTITUTE(IF(O25<>"",O25,IF(LEFT(TRIM(N25),1)="9",N25,""))," ",""),"+351",""),"-",""),9),"Abrir WhatsApp")) -> Abrir WhatsApp | AM25: Sem área do aluno; testes de código online alojados em educacao-rodoviaria.pt (http://www.educacao-rodoviaria.pt/testesonline/ouriense/); inscrição por formulário web | AN25: Praceta Prof. António de Oliveira, 4, 2490-502 Ourém | AO25: https://www.espadaeoliveira.pt/ouriense.php; https://www.espadaeoliveira.pt/contactos_ouriense.php; https://escola-de-conducao.pt/escola-de-conducao-ouriense-306307.html; https://www.testesdecodigogratis.com/escola-de-conducao/ouriense/; https://www.imt-ip.pt/wp-content/uploads/2025/01/EscolasdeConducao-2021.pdf
A26: 25 | B26: A | C26: 6.6 | D26: Novo | E26: Pedro | F26: grupo | G26: Lisboa | H26: Lourinhã | I26: Lourinhã | J26: Escola de Condução Dinossauro | K26: Bordalo (segundo o bomcondutor; não confirmado) | N26: 261 419 702 | X26: Presencial/telefone | AA26: 410 | AD26: Volume alto (410) sem presença digital própria; possivelmente integra o grupo Bordalo (Caldas da Rainha) - confirmar | AH26: 0 | AL26: =IF(IF(O26<>"",O26,IF(LEFT(TRIM(N26),1)="9",N26,""))="","",HYPERLINK("https://wa.me/351"&LEFT(SUBSTITUTE(SUBSTITUTE(SUBSTITUTE(IF(O26<>"",O26,IF(LEFT(TRIM(N26),1)="9",N26,""))," ",""),"+351",""),"-",""),9),"Abrir WhatsApp")) | AN26: Rua (Casal) Santa Catarina, nº 1, 2530-116 Lourinhã | AO26: https://www.bomcondutor.pt/escolas/escola/dinossauro; https://www.autonews.pt/escolas-de-conducao/dir/d/lisboa/c/lourinha/p-2359/escola-conducao-dinossauro/; https://passaprimeira.xyz/distritos-regioes/lisboa/concelhos/lourinha/escolas/; https://www.imt-ip.pt/wp-content/uploads/2025/01/EscolasdeConducao-2021.pdf
A27: 26 | B27: A | C27: 6.5 | D27: Novo | E27: Pedro | F27: grupo | G27: Leiria | H27: Leiria | I27: Leiria | J27: Escola de Condução Esteves - Leiria | K27: Escolas de Condução Esteves | N27: 244 882 600 | O27: 918 732 181 | Q27: escola.esteves@gmail.com | R27: https://ec-esteves.pt/ | S27: https://www.facebook.com/escolaesteves | U27: 4.6 | V27: 18 | X27: Telefone/secretaria; formulário de contacto no site | Y27: Sim | Z27: Secretaria dias úteis 9h-12h / 14h-19h30; Sábado 9h30-12h (ABERTO sábado de manhã); aulas de código seg-sáb 10h-12h | AA27: 380 | AB27: B, CAM, TCC, tratores agrícolas | AD27: Grupo com 3 escolas (Leiria, Vieira de Leiria, Clube do Condutor - Pombal); 380 exames 2021; sem app | AH27: 0 | AL27: =IF(IF(O27<>"",O27,IF(LEFT(TRIM(N27),1)="9",N27,""))="","",HYPERLINK("https://wa.me/351"&LEFT(SUBSTITUTE(SUBSTITUTE(SUBSTITUTE(IF(O27<>"",O27,IF(LEFT(TRIM(N27),1)="9",N27,""))," ",""),"+351",""),"-",""),9),"Abrir WhatsApp")) -> Abrir WhatsApp | AM27: Site WordPress sem área do aluno; link "Testes Online" | AN27: Estrada da Estação, Lt. 1 - Lj. 52, 2415-440 Leiria (IMT: Rua António Alves Espírito Santo, Lote 1, Loja 92) | AO27: https://passaprimeira.xyz/distritos-regioes/leiria/concelhos/leiria/escolas/esteves-00766/; https://ec-esteves.pt/contactos/; https://ec-esteves.pt/horarios/; https://escola-de-conducao.pt/escola-de-conducao-esteves-305910.html
A28: 27 | B28: A | C28: 6.5 | D28: Novo | E28: Pedro | F28: grupo | G28: Lisboa | H28: Cadaval | I28: Cadaval | J28: Escola de Condução Auto do Cadaval (MegaDriving) | K28: MegaDriving (10 escolas: Cadaval, Painho, Merceana, Alenquer, Lourinhã, Campelos, Bombarral, Caldas da Rainha, Atouguia da Baleia, Castanheira do Ribatejo) | N28: 262 696 231 | O28: 961 147 180 | Q28: autocadaval.ec@gmail.com | R28: https://www.megadriving.com.pt/ec_cadaval.php | S28: https://www.facebook.com/MegaDrivingEC/ | X28: Presencial/telefone; 'Aulas teóricas e práticas em horário alargado, de acordo com as tuas necessidades!' (site); sem marcação online visível | Y28: Sim | Z28: Secretaria 2ª-6ª 10h-13h e 15h-20h; Sábado 10h-13h (ABERTO sábado de manhã) | AA28: 365 | AB28: Todas as categorias (inclui pesados de passageiros); o grupo dá formação CAM, TCC, ADR, tacógrafos | AD28: Grupo multi-escola (MegaDriving, 10 escolas, 6 no âmbito) sem app/plataforma de aluno; escola mais antiga da região (1971) | AH28: 0 | AL28: =IF(IF(O28<>"",O28,IF(LEFT(TRIM(N28),1)="9",N28,""))="","",HYPERLINK("https://wa.me/351"&LEFT(SUBSTITUTE(SUBSTITUTE(SUBSTITUTE(IF(O28<>"",O28,IF(LEFT(TRIM(N28),1)="9",N28,""))," ",""),"+351",""),"-",""),9),"Abrir WhatsApp")) -> Abrir WhatsApp | AM28: Site do grupo (megadriving.com.pt) só tem formulário de contacto e página de inscrição; sem área do aluno nem links para AGEOnline/BDrive/ALSIS | AN28: Rua D. Fernando, 55 - 1º, 2550-142 Cadaval | AO28: https://www.megadriving.com.pt/ec_cadaval.php; https://www.megadriving.com.pt/; https://passaprimeira.xyz/distritos-regioes/lisboa/concelhos/cadaval/escolas/; https://www.imt-ip.pt/wp-content/uploads/2025/01/EscolasdeConducao-2021.pdf; https://www.municipiosefreguesias.pt/entidade/166451/escola-de-conducao-auto-do-cadaval
A29: 28 | B29: A | C29: 6.5 | D29: Novo | E29: Pedro | F29: grupo | G29: Viseu | H29: Viseu | I29: Viseu | J29: Escolas de Condução Viriato | K29: Escolas de Condução Viriato (Viriato + ex-Viseense/Xandey + Etapas & Objectivos) | N29: 232422907 | O29: 927539210 | Q29: ecviriato@outlook.pt | R29: https://ecviriato.pt | S29: https://www.facebook.com/escoladeconducaoviriato | T29: https://www.instagram.com/escoladeconducaoviriato | U29: 4.3 | V29: 40 | W29: Área do aluno própria no site (login por NIF + senha, /login/) + inscrição online; fornecedor e funcionalidades desconhecidos | X29: Presencial/telefone com a secretaria (avaliações: 'relativamente às marcações de aulas, são super acessíveis'; 'dando bastantes alternativas'); sem evidência de marcação online | Y29: Sim | Z29: Seg-Sex 10h-12h, 14h-19h30; Sáb 10h-12h | AA29: 790 | AB29: A1, A2, A, B, B1, C, C+E, D (site: única em Viseu com todas as categorias); também CAM, formação de instrutores (Etapas & Objectivos), Condução para Todos | AC29: Portal da Queixa 31/01/2022 (sem resolução): aluno inscrito em 2019 perde prazo de exame; resposta por telefone 'não havia nada a fazer' - https://portaldaqueixa.com/brands/escola-de-conducao-viriato/complaints/escola-de-conducao-viriato-carta-de-conducao-70821422; Avaliação 1/5 (10/03/2022): 'Justificasse sempre com o Covid. Para tirar uma carta quasse 1 anos' - https://escola-de-conducao.pt/escolas-de-conducao-viriato-306062.html; Portal da Queixa 16/04/2019: demora no exame CAM - https://portaldaqueixa.com/brands/escola-de-conducao-viriato | AD29: Maior escola do concelho (790 provas 2021); grupo (fusão com Viseense + centro de formação Etapas & Objectivos); sinais de dor documentados; presença social muito ativa (FB 4193 seguidores/46 a falar; IG 1296 posts). Atenção: já tem área do aluno própria (login NIF) - verificar se inclui marcação de aulas. | AH29: 0 | AL29: =IF(IF(O29<>"",O29,IF(LEFT(TRIM(N29),1)="9",N29,""))="","",HYPERLINK("https://wa.me/351"&LEFT(SUBSTITUTE(SUBSTITUTE(SUBSTITUTE(IF(O29<>"",O29,IF(LEFT(TRIM(N29),1)="9",N29,""))," ",""),"+351",""),"-",""),9),"Abrir WhatsApp")) -> Abrir WhatsApp | AM29: https://ecviriato.pt/login/login.php; https://ecviriato.pt/inscricao-online/ | AN29: Praça de Goa, Lote/Bloco 14 R/C, 3510-069 Viseu | AO29: https://ecviriato.pt/; https://ecviriato.pt/login/login.php; https://escola-de-conducao.pt/escolas-de-conducao-viriato-306062.html; https://portaldaqueixa.com/brands/escola-de-conducao-viriato; https://www.imt-ip.pt/wp-content/uploads/2025/07/EntidadesReconhecidas-IMT-MinistracaoDeCursosDeFormacao.pdf; https://www.facebook.com/escoladeconducaoviriato; https://www.instagram.com/escoladeconducaoviriato/
A30: 29 | B30: A | C30: 6.4 | D30: Novo | E30: Pedro | F30: grupo | G30: Leiria | H30: Marinha Grande | I30: Vieira de Leiria | J30: Escola de Condução Esteves - Vieira de Leiria | K30: Escolas de Condução Esteves | N30: 244 691 902 | O30: 912 265 148 | Q30: escola.esteves.vieira@gmail.com | R30: https://ec-esteves.pt/ | S30: https://www.facebook.com/escolaesteves | U30: 4.6 | V30: 8 | X30: Telefone/secretaria | Y30: Sim | Z30: Secretaria dias úteis 10h-12h30 / 14h30-20h; FECHADO ao sábado | AA30: 346 | AD30: Grupo Esteves (3 escolas); 346 exames 2021 | AH30: 0 | AL30: =IF(IF(O30<>"",O30,IF(LEFT(TRIM(N30),1)="9",N30,""))="","",HYPERLINK("https://wa.me/351"&LEFT(SUBSTITUTE(SUBSTITUTE(SUBSTITUTE(IF(O30<>"",O30,IF(LEFT(TRIM(N30),1)="9",N30,""))," ",""),"+351",""),"-",""),9),"Abrir WhatsApp")) -> Abrir WhatsApp | AN30: Estádio Tomé Albano Feteira, Rua de Leiria - 2430-773 Vieira de Leiria | AO30: https://passaprimeira.xyz/distritos-regioes/leiria/concelhos/marinha-grande/escolas/esteves-da-vieira-01170/; https://ec-esteves.pt/contactos/; https://ec-esteves.pt/horarios/; https://escola-de-conducao.pt/escola-de-conducao-esteves-da-vieira-305908.html
A31: 30 | B31: A | C31: 6.4 | D31: Novo | E31: Pedro | F31: grupo | G31: Santarém | H31: Ourém | I31: Fátima | J31: Escola de Condução Fatimense | K31: Espada & Oliveira (Ouriense, Fatimense, Caxariense) | N31: 249 532 161 | O31: 919 613 040 / 933 890 047 | Q31: ec-fatimense@espadaeoliveira.com | R31: https://www.espadaeoliveira.pt/fatimense.php | S31: https://www.facebook.com/pages/ESCOLA-DE-CONDU%C3%87%C3%83O-OURIENSE/117550408321810 | U31: 4 | V31: 4 | X31: Telefone/presencial; pré-inscrição por formulário no site | Y31: Sim | Z31: Seg-Sex 10:30-13:00 e 15:00-19:30; Sábado 09:00-12:00 (ABERTO sábado) | AA31: 98 | AC31: 'Gama de preços muito elevada' (1/5, 2017) - https://escola-de-conducao.pt/escola-de-conducao-fatimense-306031.html | AD31: Delegação do grupo Espada & Oliveira (3 escolas). | AH31: 0 | AL31: =IF(IF(O31<>"",O31,IF(LEFT(TRIM(N31),1)="9",N31,""))="","",HYPERLINK("https://wa.me/351"&LEFT(SUBSTITUTE(SUBSTITUTE(SUBSTITUTE(IF(O31<>"",O31,IF(LEFT(TRIM(N31),1)="9",N31,""))," ",""),"+351",""),"-",""),9),"Abrir WhatsApp")) -> Abrir WhatsApp | AM31: Sem área do aluno; testes de código online alojados em educacao-rodoviaria.pt (http://www.educacao-rodoviaria.pt/testesonline/ouriense/); inscrição por formulário web | AN31: Estrada Principal de Fátima, Edifício Fátima, Loja 2 R/C, 2495-552 Fátima | AO31: https://www.espadaeoliveira.pt/contactos_fatimense.php; https://escola-de-conducao.pt/escola-de-conducao-fatimense-306031.html; https://www.testesdecodigogratis.com/escola-de-conducao/fatimense/; https://www.imt-ip.pt/wp-content/uploads/2025/01/EscolasdeConducao-2021.pdf
A32: 31 | B32: A | C32: 6.4 | D32: Novo | E32: Pedro | F32: grupo | G32: Santarém | H32: Santarém | I32: Santarém (S. Domingos) | J32: Escola de Condução Santarém | K32: Possível grupo Andrade (Escola de Condução Andrade Lda; mesma morada listada como 'Escola de Condução de Coruche') — a confirmar | N32: 243 372 579 | O32: 914 895 609 | Q32: geral@ecsantarem.com | R32: https://ecsantarem.com/ | S32: https://www.facebook.com/escoladeconducao.santarem/ | U32: 4.4 | V32: 31 | X32: Telefone/presencial; teóricas sem marcação prévia (site) | Y32: Sim | Z32: Site: Semana 09:00-18:00, Sábado 09:00-13:00 (secretaria 2ª-6ª 09:00-12:00/14:30-19:00); aulas práticas 2ª-6ª 09-13/14-20 e Sábado 09:00-13:00; Google: Sáb 09:00-13:00 (ABERTO SÁBADO) | AA32: 349 | AB32: A1, A2, A, B, C, CE (+ CAM, ADR, Táxi) | AC32: 'Já tentei ligar mas não atendem, tbm já mandei um e-mail e não tive retorno' — https://escola-de-conducao.pt/escola-de-conducao-de-santarem-306347.html | AD32: Escola de volume médio-alto com formação profissional (CAM/ADR), sem app/área do aluno, queixa de não atender telefone; possível ligação a Coruche | AH32: 0 | AL32: =IF(IF(O32<>"",O32,IF(LEFT(TRIM(N32),1)="9",N32,""))="","",HYPERLINK("https://wa.me/351"&LEFT(SUBSTITUTE(SUBSTITUTE(SUBSTITUTE(IF(O32<>"",O32,IF(LEFT(TRIM(N32),1)="9",N32,""))," ",""),"+351",""),"-",""),9),"Abrir WhatsApp")) -> Abrir WhatsApp | AM32: Site WordPress institucional (ecsantarem.com) sem área do aluno, e-learning ou link a plataforma; só formulário de contacto | AN32: Av. Marquês de Pombal nº 117 R/C (junto à Rotunda da Fonte Luminosa), S. Domingos, 2005-170 Santarém | AO32: https://ecsantarem.com/; https://escola-de-conducao.pt/escola-de-conducao-de-santarem-306347.html; https://www.andardemoto.pt/escolas-de-conducao/dir/d/santarem/c/santarem/p-2111/escola-de-conducao-de-coruche/; https://escolasconducao.com/escola/escola-de-conducao-andrade-lda; https://www.imt-ip.pt/wp-content/uploads/2025/01/EscolasdeConducao-2021.pdf
A33: 32 | B33: A | C33: 6.4 | D33: Novo | E33: Pedro | F33: grupo | G33: Lisboa | H33: Arruda dos Vinhos | I33: Arruda dos Vinhos | J33: Escola de Condução Automóvel Arrudense | K33: Sobralense / Arrudense (provável: partilham o telefone 261 941 052) | N33: 263 975 100; 261 941 052 | S33: https://www.facebook.com/escola.arrudense | X33: Presencial/telefone | AA33: 351 | AD33: Provável grupo com a Sobralense (telefone partilhado; diretório refere uma 'Filial A. Vinhos' na mesma morada); volume médio | AH33: 0 | AL33: =IF(IF(O33<>"",O33,IF(LEFT(TRIM(N33),1)="9",N33,""))="","",HYPERLINK("https://wa.me/351"&LEFT(SUBSTITUTE(SUBSTITUTE(SUBSTITUTE(IF(O33<>"",O33,IF(LEFT(TRIM(N33),1)="9",N33,""))," ",""),"+351",""),"-",""),9),"Abrir WhatsApp")) | AN33: Rua Manuel Policarpo Martins, nº 15 R/C Dto, 2630-110 Arruda dos Vinhos | AO33: https://www.bomcondutor.pt/escolas/escola/arrudense; https://www.municipiosefreguesias.pt/entidade/166472/escola-de-conducao-automovel-arrudense-lda--arruda-dos-vinhos; https://passaprimeira.xyz/distritos-regioes/lisboa/concelhos/arruda-dos-vinhos/escolas/; https://www.imt-ip.pt/wp-content/uploads/2025/01/EscolasdeConducao-2021.pdf
A34: 33 | B34: A | C34: 6.3 | D34: Novo | E34: Pedro | F34: grupo | G34: Coimbra | H34: Coimbra | I34: Coimbra (Solum) | J34: Escola de Condução Quinta das Flores | K34: Possível grupo Capas Negras / Quinta das Flores / Solum (não confirmado) | O34: 915 742 412 | S34: https://www.facebook.com/ecquintadasflores/ | U34: 4.7 | V34: 55 | Y34: Sim | Z34: Seg-Sex 10:00-13:00 / 14:00-20:00; Sábado 10:00-13:00 (aberto ao sábado) | AA34: 454 | AC34: 'não sabe cumprir a sua palavra nem os seus prazos' (https://escola-de-conducao.pt/escola-de-conducao-quinta-das-flores-306247.html); 'péssimo planejamento das últimas aulas de código do dia ficando em sobrelotação' (idem) | AD34: Volume 454 provas (2021), queixas de planeamento/prazos, provável grupo com Capas Negras/Solum | AH34: 0 | AL34: =IF(IF(O34<>"",O34,IF(LEFT(TRIM(N34),1)="9",N34,""))="","",HYPERLINK("https://wa.me/351"&LEFT(SUBSTITUTE(SUBSTITUTE(SUBSTITUTE(IF(O34<>"",O34,IF(LEFT(TRIM(N34),1)="9",N34,""))," ",""),"+351",""),"-",""),9),"Abrir WhatsApp")) -> Abrir WhatsApp | AM34: Sem website identificado | AN34: Av. Dr. Mendes Silva, loja 285, 3030-193 Coimbra | AO34: https://escola-de-conducao.pt/escola-de-conducao-quinta-das-flores-306247.html; https://www.imt-ip.pt/wp-content/uploads/2025/01/EscolasdeConducao-2021.pdf
A35: 34 | B35: A | C35: 6.2 | D35: Novo | E35: Pedro | F35: grupo | G35: Leiria | H35: Pombal | I35: Pombal (Várzea) | J35: Escola de Condução Cardal | K35: Provável grupo EC Caldas (inferido) | O35: 917 774 734 | R35: http://www.eccaldas.pt/ (ligado na ficha Google) | U35: 4.7 | V35: 33 | X35: Telefone/presencial | Y35: Sim | Z35: 2ª-6ª 10h-12h30 / 14h-20h; Sábado 9h-13h (ABERTO sábado) | AA35: 168 | AC35: "Péssimo atendimento, não fornece as informações necessárias, parece que estamos a pedir-lhe favor" (Google 1★, 01/2023) https://escola-de-conducao.pt/escola-de-conducao-cardal-306425.html | AD35: Ficha Google aponta para eccaldas.pt (provável grupo com EC Caldas/Nova Rainha); queixa de atendimento | AH35: 0 | AL35: =IF(IF(O35<>"",O35,IF(LEFT(TRIM(N35),1)="9",N35,""))="","",HYPERLINK("https://wa.me/351"&LEFT(SUBSTITUTE(SUBSTITUTE(SUBSTITUTE(IF(O35<>"",O35,IF(LEFT(TRIM(N35),1)="9",N35,""))," ",""),"+351",""),"-",""),9),"Abrir WhatsApp")) -> Abrir WhatsApp | AN35: Av. Heróis do Ultramar, 177 - 3100-462 Pombal (IMT: Rua Marechal António Spínola, Ed. Intermarché, Várzea) | AO35: https://passaprimeira.xyz/distritos-regioes/leiria/concelhos/pombal/escolas/cardal-01394/; https://escola-de-conducao.pt/escola-de-conducao-cardal-306425.html
A36: 35 | B36: A | C36: 6.2 | D36: Novo | E36: Pedro | F36: grupo | G36: Leiria | H36: Caldas da Rainha | I36: Caldas da Rainha | J36: Escola de Condução Nova Rainha | K36: Provável grupo EC Caldas (mesma morada IMT que EC Caldas) | AA36: 294 | AD36: Mesma morada IMT que a EC Caldas (provável grupo); 294 exames 2021 | AH36: 0 | AL36: =IF(IF(O36<>"",O36,IF(LEFT(TRIM(N36),1)="9",N36,""))="","",HYPERLINK("https://wa.me/351"&LEFT(SUBSTITUTE(SUBSTITUTE(SUBSTITUTE(IF(O36<>"",O36,IF(LEFT(TRIM(N36),1)="9",N36,""))," ",""),"+351",""),"-",""),9),"Abrir WhatsApp")) | AN36: Rua Cardeal Alpedrinha, 72 A - 2500-843 Caldas da Rainha | AO36: https://passaprimeira.xyz/distritos-regioes/leiria/concelhos/caldas-da-rainha/escolas/nova-rainha-01333/
